##7.1异常的体系  
Throwable 所有异常或者错误类的超类.  
Error     错误,错误一般是jvm或者是硬件引发的问题,一半不会去通过代码去处理错误.  
Exception 异常,需要通过代码去处理.  

    public class l {
        public static void main(String arg[]) {
            Throwable t = new Throwable("头疼");    //创建一个Throwabl类型对象
            String tostr = t.toString();          
            System.out.println("tostring:" + tostr);
            String get = t.getMessage();
            System.out.println("getMessage:" + get);
            t.printStackTrace();    
            String loc = t.getLocalizedMessage();
            System.out.println("getLocalizedMessage:" + loc);
        }
    }
输出:
tostring:java.lang.Throwable: 头疼  
getMessage:头疼  
java.lang.Throwable: 头疼  
	at l.main(l.java:13)  
getLocalizedMessage:头疼  

Throwable 常用的方法:  
1. toString() 返回当前一场对象的完整类名  
2. getMessage()返回的是创建throwable传入的字符串信息  
3. printStackTrace() 打印异常的栈信息  
***
##7.2处理异常
###7.2.1使用try..catch处理异常


    public class l {
        public static void main(String arg[]) {
            A (4,0);
        }
        public static void A(int a ,int b) {
            int c = 0;
            try {
            c = a / b;
            }catch(ArithmeticException q) {  //捕获类型小
                q.printStackTrace();
                System.out.println("出错了"+q.toString());
            }catch(Exception e) {    //要放在最后,它捕获类型大
                e.printStackTrace();
                System.out.println("捕获范围大");
            }
            System.out.println("c="+c);
        }
    }

输出:  
java.lang.ArithmeticException: / by zero  
	at l.A(l.java:8)  
	at l.main(l.java:3)  
出错了java.lang.ArithmeticException: / by zero  
c=0  

捕获处理要注意的细节:  
1. 如果try块中代码除了异常经过了处理之后,那么try-catch块外面的代码可以正常执行.  
2. 如果try块中出了异常的代码,那么在try块中出现异常代码后面的代码是不会执行了.  
3. 一个try块后面是可以跟有多个catch块的,也就是一个try块可以捕获多种异常的类型.  
4. 一个try块可以捕获多种异常的类型,但是捕获的异常类型必须从小到大进行捕获,否则编译报错.  
***
###7.2.2抛出异常


    public class l {
        public static void main(String arg[]) {
            try{
                int[] arr = null;
                A(4,2,arr);
            }catch(Exception e) {
                System.out.println("出现了异常");
                e.printStackTrace();
            }
        }
        public static void A(int a ,int b,int[] arr)throws Exception,NullPointerException {
            if(b==0) {                              //使用throws声明了抛出
                throw new Exception();//抛出一个异常对象
                //throw new NullPointerException(); 不能在一个情况同时抛出两个异常
            }else if(arr ==null){
                throw new NullPointerException();
            }
            int c = 0;
            try {
            c = a / b;
            }catch(ArithmeticException q) {  
                q.printStackTrace();
                System.out.println("出错了"+q.toString());
            }
            System.out.println("c="+c);
        }
    }

输出:  
出现了异常  
java.lang.NullPointerException  
	at l.A(l.java:16)  
	at l.main(l.java:5)  

抛出处理要注意的细节:  
1. 如果一个方法的内部抛出了一个编译时异常对象,那么必须在方法上声明抛出.
2. 如果调用了一个声明抛出编译时异常的方法,那么调用者必须要处理异常.
3. 如果一个方法内部抛出了一个异常对象,那么throw语句后面的代码都不会再执行了
4. 在一种情况下,只能抛出一种异常类型对象.  

运行时异常:RuntimeException以及RuntimeException的子类都是属于运行时异常.  
运行时异常:如果一个方法内部抛出了一个运行时异常,那么方法上可以声明,也可以不声明,调用者可处理也可以不处理.  
编译时异常:除了运行时异常就是编译时异常.  
编译时异常:如果一个方法内部抛出了一个编译时异常对象,那么方法上必须声明,调用者必须处理.  

throw与throws两个关键字区别:
1. throw关键字是用于方法内部的,throws是用于方法声明.
2. throw关键字是用于方法内部抛出一个异常对象的,thorws关键字是用于在方法声明上声明抛出的异常类型.
3. throw关键字后面只能有一个异常对象,throws后面一次可以声明抛出多种类型的异常.
***
###7.3自定义异常  


    public class l {
        public static void main(String arg[]) {
        	String ip = null;
        	try {                                  //异常一旦抛出,必须要处理
        		QQ(ip);
        	}catch(NoipException a){   
        		a.printStackTrace();
        		System.out.println("没有插上网线");
        	}
        }
        public static void QQ(String ip)throws NoipException{ //需要用throws声明
        	if(ip==null) {
        		throw new NoipException("没插网线");
        	}
        }
    }
    class NoipException extends Exception {   //自定义异常类
        public NoipException(String message){
        super(message);       //使用父类构造方法
        }
    }

自定义异常,即是继承Exception类,然后添加新东西.使用时和之前一样,在方法上要声明抛出.  
***
###7.4finally块
finnaly块的使用前提是必须要存在try块才能使用.  
finally块的代码在任何情况下都会执行,除了jvm退出.  
finally块非常适合做资源释放的工作,这样可以保证资源文件在任何情况下都会被释放.  

try块的三种组合方式:  
第一种:  
try{  
可能发生异常的代码}catch(捕获的异常类型 变量名){  
处理异常的代码}  
***
第二种:
try{  
可能发生异常的代码}catch(捕获的异常类型 变量名){  
处理异常的代码}  
finally{资源释放}  
***
第三种:
try{  
可能发生异常的代码}
finally{资源释放}  
